Traceback (most recent call last):
  File "C:\Users\cross\AppData\Local\uv\cache\archive-v0\Lh2DNl-8n4Wvb4Kf65VNq\Lib\site-packages\anyio\streams\memory.py", line 111, in receive
    return self.receive_nowait()
           ~~~~~~~~~~~~~~~~~~~^^
  File "C:\Users\cross\AppData\Local\uv\cache\archive-v0\Lh2DNl-8n4Wvb4Kf65VNq\Lib\site-packages\anyio\streams\memory.py", line 106, in receive_nowait
    raise WouldBlock
anyio.WouldBlock

During handling of the above exception, another exception occurred:

Traceback (most recent call last):
  File "C:\Python313\Lib\asyncio\runners.py", line 118, in run
    return self._loop.run_until_complete(task)
           ~~~~~~~~~~~~~~~~~~~~~~~~~~~~~^^^^^^
  File "C:\Python313\Lib\asyncio\base_events.py", line 725, in run_until_complete
    return future.result()
           ~~~~~~~~~~~~~^^
  File "C:\Users\cross\AppData\Local\uv\cache\archive-v0\Lh2DNl-8n4Wvb4Kf65VNq\Lib\site-packages\mcp_server_fetch\server.py", line 288, in serve
    await server.run(read_stream, write_stream, options, raise_exceptions=True)
  File "C:\Users\cross\AppData\Local\uv\cache\archive-v0\Lh2DNl-8n4Wvb4Kf65VNq\Lib\site-packages\mcp\server\lowlevel\server.py", line 574, in run
    async with AsyncExitStack() as stack:
               ~~~~~~~~~~~~~~^^
  File "C:\Python313\Lib\contextlib.py", line 768, in __aexit__
    raise exc
  File "C:\Python313\Lib\contextlib.py", line 751, in __aexit__
    cb_suppress = await cb(*exc_details)
                  ^^^^^^^^^^^^^^^^^^^^^^
  File "C:\Users\cross\AppData\Local\uv\cache\archive-v0\Lh2DNl-8n4Wvb4Kf65VNq\Lib\site-packages\mcp\shared\session.py", line 218, in __aexit__
    return await self._task_group.__aexit__(exc_type, exc_val, exc_tb)
           ^^^^^^^^^^^^^^^^^^^^^^^^^^^^^^^^^^^^^^^^^^^^^^^^^^^^^^^^^^^
  File "C:\Users\cross\AppData\Local\uv\cache\archive-v0\Lh2DNl-8n4Wvb4Kf65VNq\Lib\site-packages\anyio\_backends\_asyncio.py", line 776, in __aexit__
    raise exc_val
  File "C:\Users\cross\AppData\Local\uv\cache\archive-v0\Lh2DNl-8n4Wvb4Kf65VNq\Lib\site-packages\mcp\server\lowlevel\server.py", line 585, in run
    async with anyio.create_task_group() as tg:
               ~~~~~~~~~~~~~~~~~~~~~~~^^
  File "C:\Users\cross\AppData\Local\uv\cache\archive-v0\Lh2DNl-8n4Wvb4Kf65VNq\Lib\site-packages\anyio\_backends\_asyncio.py", line 776, in __aexit__
    raise exc_val
  File "C:\Users\cross\AppData\Local\uv\cache\archive-v0\Lh2DNl-8n4Wvb4Kf65VNq\Lib\site-packages\mcp\server\lowlevel\server.py", line 586, in run
    async for message in session.incoming_messages:
    ...<8 lines>...
        )
  File "C:\Users\cross\AppData\Local\uv\cache\archive-v0\Lh2DNl-8n4Wvb4Kf65VNq\Lib\site-packages\anyio\abc\_streams.py", line 41, in __anext__
    return await self.receive()
           ^^^^^^^^^^^^^^^^^^^^
  File "C:\Users\cross\AppData\Local\uv\cache\archive-v0\Lh2DNl-8n4Wvb4Kf65VNq\Lib\site-packages\anyio\streams\memory.py", line 119, in receive
    await receive_event.wait()
  File "C:\Users\cross\AppData\Local\uv\cache\archive-v0\Lh2DNl-8n4Wvb4Kf65VNq\Lib\site-packages\anyio\_backends\_asyncio.py", line 1774, in wait
    await self._event.wait()
  File "C:\Python313\Lib\asyncio\locks.py", line 213, in wait
    await fut
asyncio.exceptions.CancelledError

During handling of the above exception, another exception occurred:

Traceback (most recent call last):
  File "<frozen runpy>", line 198, in _run_module_as_main
  File "<frozen runpy>", line 88, in _run_code
  File "C:\Users\cross\AppData\Local\uv\cache\archive-v0\Lh2DNl-8n4Wvb4Kf65VNq\Scripts\mcp-server-fetch.exe\__main__.py", line 10, in <module>
    sys.exit(main())
             ~~~~^^
  File "C:\Users\cross\AppData\Local\uv\cache\archive-v0\Lh2DNl-8n4Wvb4Kf65VNq\Lib\site-packages\mcp_server_fetch\__init__.py", line 21, in main
    asyncio.run(serve(args.user_agent, args.ignore_robots_txt, args.proxy_url))
    ~~~~~~~~~~~^^^^^^^^^^^^^^^^^^^^^^^^^^^^^^^^^^^^^^^^^^^^^^^^^^^^^^^^^^^^^^^^
  File "C:\Python313\Lib\asyncio\runners.py", line 195, in run
    return runner.run(main)
           ~~~~~~~~~~^^^^^^
  File "C:\Python313\Lib\asyncio\runners.py", line 123, in run
    raise KeyboardInterrupt()
KeyboardInterrupt
